<?xml version="1.0" encoding="utf-8"?>
<!-- This URDF was automatically created by SolidWorks to URDF Exporter! Originally created by Stephen Brawner (brawner@gmail.com) 
     Commit Version: 1.6.0-4-g7f85cfe  Build Version: 1.6.7995.38578
     For more information, please see http://wiki.ros.org/sw_urdf_exporter -->
<robot
  name="larva54">
  <link
    name="base_link">
    <inertial>
      <origin
        xyz="-0.000499999999999973 0 -4.44089209850063E-16"
        rpy="0 0 0" />
      <mass
        value="5.02654824574367E-05" />
      <inertia
        ixx="4.02123859659494E-10"
        ixy="-5.68086652660395E-26"
        ixz="-7.06335332977124E-26"
        iyy="2.05250720034533E-10"
        iyz="1.93870456067116E-26"
        izz="2.05250720034533E-10" />
    </inertial>
    <visual>
      <origin
        xyz="0 0 0"
        rpy="0 0 0" />
      <geometry>
        <mesh
          filename="package://larva54/meshes/base_link.STL" />
      </geometry>
      <material
        name="">
        <color
          rgba="0.792156862745098 0.819607843137255 0.933333333333333 1" />
      </material>
    </visual>
    <collision>
      <origin
        xyz="0 0 0"
        rpy="0 0 0" />
      <geometry>
        <mesh
          filename="package://larva54/meshes/base_link.STL" />
      </geometry>
    </collision>
  </link>
  <link
    name="rsec11">
    <inertial>
      <origin
        xyz="0.0150000000000001 -0.0272479653741931 4.44089209850063E-16"
        rpy="0 0 0" />
      <mass
        value="0.00814247932954212" />
      <inertia
        ixx="2.58090802782193E-06"
        ixy="-3.71116898050847E-21"
        ixz="-6.24497133474091E-22"
        iyy="9.04351126416434E-07"
        iyz="1.02702744854584E-20"
        izz="3.27245109843997E-06" />
    </inertial>
    <visual>
      <origin
        xyz="0 0 0"
        rpy="0 0 0" />
      <geometry>
        <mesh
          filename="package://larva54/meshes/rsec11.STL" />
      </geometry>
      <material
        name="">
        <color
          rgba="0.792156862745098 0.819607843137255 0.933333333333333 1" />
      </material>
    </visual>
    <collision>
      <origin
        xyz="0 0 0"
        rpy="0 0 0" />
      <geometry>
        <mesh
          filename="package://larva54/meshes/rsec11.STL" />
      </geometry>
    </collision>
  </link>
  <joint
    name="rjoint11"
    type="revolute">
    <origin
      xyz="-0.031 0 0"
      rpy="0 0 0" />
    <parent
      link="base_link" />
    <child
      link="rsec11" />
    <axis
      xyz="1 0 0" />
    <limit
      lower="-3.14"
      upper="3.14"
      effort="100"
      velocity="100" />
  </joint>
  <link
    name="psec11">
    <inertial>
      <origin
        xyz="5.82867087928207E-16 -0.0444356741319128 -4.44089209850063E-16"
        rpy="0 0 0" />
      <mass
        value="0.00950290648044837" />
      <inertia
        ixx="2.06910554500492E-06"
        ixy="1.61044855384348E-21"
        ixz="1.6362477167982E-24"
        iyy="6.3101540452144E-07"
        iyz="2.96461531539005E-21"
        izz="2.62322222113119E-06" />
    </inertial>
    <visual>
      <origin
        xyz="0 0 0"
        rpy="0 0 0" />
      <geometry>
        <mesh
          filename="package://larva54/meshes/psec11.STL" />
      </geometry>
      <material
        name="">
        <color
          rgba="0.792156862745098 0.819607843137255 0.933333333333333 1" />
      </material>
    </visual>
    <collision>
      <origin
        xyz="0 0 0"
        rpy="0 0 0" />
      <geometry>
        <mesh
          filename="package://larva54/meshes/psec11.STL" />
      </geometry>
    </collision>
  </link>
  <joint
    name="pjoint11"
    type="prismatic">
    <origin
      xyz="0.0150000000000004 -0.00800000000000095 0"
      rpy="0 0 0" />
    <parent
      link="rsec11" />
    <child
      link="psec11" />
    <axis
      xyz="0 -1 0" />
    <limit
      lower="-0.01"
      upper="0.01"
      effort="100"
      velocity="100" />
  </joint>
  <link
    name="rsec12">
    <inertial>
      <origin
        xyz="0.0149999999999993 -0.00521814457836545 -0.0282191168584589"
        rpy="0 0 0" />
      <mass
        value="0.00900245720098014" />
      <inertia
        ixx="3.53141255495156E-06"
        ixy="-1.21392399109586E-21"
        ixz="-2.01856962146286E-21"
        iyy="4.16190674038217E-06"
        iyz="-5.89210772270563E-07"
        izz="1.08447769952084E-06" />
    </inertial>
    <visual>
      <origin
        xyz="0 0 0"
        rpy="0 0 0" />
      <geometry>
        <mesh
          filename="package://larva54/meshes/rsec12.STL" />
      </geometry>
      <material
        name="">
        <color
          rgba="0.792156862745098 0.819607843137255 0.933333333333333 1" />
      </material>
    </visual>
    <collision>
      <origin
        xyz="0 0 0"
        rpy="0 0 0" />
      <geometry>
        <mesh
          filename="package://larva54/meshes/rsec12.STL" />
      </geometry>
    </collision>
  </link>
  <joint
    name="rjoint12"
    type="revolute">
    <origin
      xyz="-0.0149999999999997 -0.0720000000000022 0"
      rpy="0 0 0" />
    <parent
      link="psec11" />
    <child
      link="rsec12" />
    <axis
      xyz="1 0 0" />
    <limit
      lower="-3.14"
      upper="3.14"
      effort="100"
      velocity="100" />
  </joint>
  <link
    name="psec12">
    <inertial>
      <origin
        xyz="-4.71844785465692E-16 0.0516602747419426 5.39568389967826E-14"
        rpy="0 0 0" />
      <mass
        value="0.0113929064804486" />
      <inertia
        ixx="3.53005448855795E-06"
        ixy="-1.63493131559331E-21"
        ixz="7.98891199277559E-23"
        iyy="7.53550404521461E-07"
        iyz="1.03232140446618E-21"
        izz="4.19127116468423E-06" />
    </inertial>
    <visual>
      <origin
        xyz="0 0 0"
        rpy="0 0 0" />
      <geometry>
        <mesh
          filename="package://larva54/meshes/psec12.STL" />
      </geometry>
      <material
        name="">
        <color
          rgba="0.792156862745098 0.819607843137255 0.933333333333333 1" />
      </material>
    </visual>
    <collision>
      <origin
        xyz="0 0 0"
        rpy="0 0 0" />
      <geometry>
        <mesh
          filename="package://larva54/meshes/psec12.STL" />
      </geometry>
    </collision>
  </link>
  <joint
    name="pjoint12"
    type="prismatic">
    <origin
      xyz="0.0149999999999999 -0.00145466083047219 -0.00786663599439352"
      rpy="-1.75364613025644 0 0" />
    <parent
      link="rsec12" />
    <child
      link="psec12" />
    <axis
      xyz="0 1 0" />
    <limit
      lower="-0.01"
      upper="0.01"
      effort="100"
      velocity="100" />
  </joint>
  <link
    name="rsec13">
    <inertial>
      <origin
        xyz="0.015057761130921 0.030463230470914 0.0140445297245235"
        rpy="0 0 0" />
      <mass
        value="0.0101124572009805" />
      <inertia
        ixx="5.21578447023896E-06"
        ixy="1.42780672513027E-08"
        ixz="6.58264855104289E-09"
        iyy="1.96895737588561E-06"
        iyz="-1.88022704105014E-06"
        izz="5.18041106258412E-06" />
    </inertial>
    <visual>
      <origin
        xyz="0 0 0"
        rpy="0 0 0" />
      <geometry>
        <mesh
          filename="package://larva54/meshes/rsec13.STL" />
      </geometry>
      <material
        name="">
        <color
          rgba="0.792156862745098 0.819607843137255 0.933333333333333 1" />
      </material>
    </visual>
    <collision>
      <origin
        xyz="0 0 0"
        rpy="0 0 0" />
      <geometry>
        <mesh
          filename="package://larva54/meshes/rsec13.STL" />
      </geometry>
    </collision>
  </link>
  <joint
    name="rjoint13"
    type="revolute">
    <origin
      xyz="-0.0154623180616895 0.0842320000000001 0"
      rpy="1.75364613025644 0 0" />
    <parent
      link="psec12" />
    <child
      link="rsec13" />
    <axis
      xyz="1 0 0" />
    <limit
      lower="-3.14"
      upper="3.14"
      effort="100"
      velocity="100" />
  </joint>
  <link
    name="psec13">
    <inertial>
      <origin
        xyz="8.32667268468867E-17 0.0634854251616015 1.68753899743024E-14"
        rpy="0 0 0" />
      <mass
        value="0.0123379064804484" />
      <inertia
        ixx="4.46823934651093E-06"
        ixy="-9.88411408572198E-22"
        ixz="1.03309533318994E-22"
        iyy="8.14817904521441E-07"
        iyz="8.62914815015318E-21"
        izz="5.1830060226372E-06" />
    </inertial>
    <visual>
      <origin
        xyz="0 0 0"
        rpy="0 0 0" />
      <geometry>
        <mesh
          filename="package://larva54/meshes/psec13.STL" />
      </geometry>
      <material
        name="">
        <color
          rgba="0.792156862745098 0.819607843137255 0.933333333333333 1" />
      </material>
    </visual>
    <collision>
      <origin
        xyz="0 0 0"
        rpy="0 0 0" />
      <geometry>
        <mesh
          filename="package://larva54/meshes/psec13.STL" />
      </geometry>
    </collision>
  </link>
  <joint
    name="pjoint13"
    type="prismatic">
    <origin
      xyz="0.0154623180616888 0.00726507392751519 0.00334943291136325"
      rpy="0.431990326238117 0 0" />
    <parent
      link="rsec13" />
    <child
      link="psec13" />
    <axis
      xyz="0 1 0" />
    <limit
      lower="-0.01"
      upper="0.01"
      effort="100"
      velocity="100" />
  </joint>
  <link
    name="rsec14">
    <inertial>
      <origin
        xyz="0.015 4.44089209850063E-16 -0.0157184703636566"
        rpy="0 0 0" />
      <mass
        value="0.0137603858099909" />
      <inertia
        ixx="2.33230347484184E-06"
        ixy="-5.5595583082376E-22"
        ixz="9.95418394399463E-22"
        iyy="3.25281322158617E-06"
        iyz="-2.17052192733914E-21"
        izz="1.08923903093791E-06" />
    </inertial>
    <visual>
      <origin
        xyz="0 0 0"
        rpy="0 0 0" />
      <geometry>
        <mesh
          filename="package://larva54/meshes/rsec14.STL" />
      </geometry>
      <material
        name="">
        <color
          rgba="0.792156862745098 0.819607843137255 0.933333333333333 1" />
      </material>
    </visual>
    <collision>
      <origin
        xyz="0 0 0"
        rpy="0 0 0" />
      <geometry>
        <mesh
          filename="package://larva54/meshes/rsec14.STL" />
      </geometry>
    </collision>
  </link>
  <joint
    name="rjoint14"
    type="revolute">
    <origin
      xyz="-0.015 0.0985599999999993 0"
      rpy="-0.431990326238117 0 0" />
    <parent
      link="psec13" />
    <child
      link="rsec14" />
    <axis
      xyz="1 0 0" />
    <limit
      lower="-3.14"
      upper="3.14"
      effort="100"
      velocity="100" />
  </joint>
  <link
    name="psec14">
    <inertial>
      <origin
        xyz="-1.66533453693773E-16 0.0218035208950598 -2.22044604925031E-16"
        rpy="0 0 0" />
      <mass
        value="0.00694913649691772" />
      <inertia
        ixx="5.77071801345558E-07"
        ixy="-5.29859473379937E-22"
        ixz="-2.75929745882599E-22"
        iyy="4.75978173293698E-07"
        iyz="-5.29395592033938E-22"
        izz="1.00011721116997E-06" />
    </inertial>
    <visual>
      <origin
        xyz="0 0 0"
        rpy="0 0 0" />
      <geometry>
        <mesh
          filename="package://larva54/meshes/psec14.STL" />
      </geometry>
      <material
        name="">
        <color
          rgba="0.792156862745098 0.819607843137255 0.933333333333333 1" />
      </material>
    </visual>
    <collision>
      <origin
        xyz="0 0 0"
        rpy="0 0 0" />
      <geometry>
        <mesh
          filename="package://larva54/meshes/psec14.STL" />
      </geometry>
    </collision>
  </link>
  <joint
    name="pjoint14"
    type="prismatic">
    <origin
      xyz="0.0150000000000003 0 0.00799999999999912"
      rpy="1.5707963267949 0 0" />
    <parent
      link="rsec14" />
    <child
      link="psec14" />
    <axis
      xyz="0 1 0" />
    <limit
      lower="-0.01"
      upper="0.01"
      effort="100"
      velocity="100" />
  </joint>
  <link
    name="rsec21">
    <inertial>
      <origin
        xyz="0.0149999999999993 -0.0272479653741917 -4.44089209850063E-16"
        rpy="0 0 0" />
      <mass
        value="0.0081424793295423" />
      <inertia
        ixx="2.58090802782197E-06"
        ixy="-4.06460921165278E-21"
        ixz="-8.36274219475207E-22"
        iyy="9.04351126416445E-07"
        iyz="2.43521972335611E-21"
        izz="3.27245109844002E-06" />
    </inertial>
    <visual>
      <origin
        xyz="0 0 0"
        rpy="0 0 0" />
      <geometry>
        <mesh
          filename="package://larva54/meshes/rsec21.STL" />
      </geometry>
      <material
        name="">
        <color
          rgba="0.792156862745098 0.819607843137255 0.933333333333333 1" />
      </material>
    </visual>
    <collision>
      <origin
        xyz="0 0 0"
        rpy="0 0 0" />
      <geometry>
        <mesh
          filename="package://larva54/meshes/rsec21.STL" />
      </geometry>
    </collision>
  </link>
  <joint
    name="rjoint21"
    type="revolute">
    <origin
      xyz="0 0 0"
      rpy="0 0 0" />
    <parent
      link="rsec12" />
    <child
      link="rsec21" />
    <axis
      xyz="1 0 0" />
    <limit
      lower="-3.14"
      upper="3.14"
      effort="100"
      velocity="100" />
  </joint>
  <link
    name="psec21">
    <inertial>
      <origin
        xyz="-1.38777878078145E-16 -0.0444356741319121 -8.88178419700125E-16"
        rpy="0 0 0" />
      <mass
        value="0.00950290648044836" />
      <inertia
        ixx="2.06910554500492E-06"
        ixy="-1.11624648795648E-21"
        ixz="4.00861393654419E-23"
        iyy="6.31015404521439E-07"
        iyz="3.78517848304265E-21"
        izz="2.62322222113118E-06" />
    </inertial>
    <visual>
      <origin
        xyz="0 0 0"
        rpy="0 0 0" />
      <geometry>
        <mesh
          filename="package://larva54/meshes/psec21.STL" />
      </geometry>
      <material
        name="">
        <color
          rgba="0.792156862745098 0.819607843137255 0.933333333333333 1" />
      </material>
    </visual>
    <collision>
      <origin
        xyz="0 0 0"
        rpy="0 0 0" />
      <geometry>
        <mesh
          filename="package://larva54/meshes/psec21.STL" />
      </geometry>
    </collision>
  </link>
  <joint
    name="pjoint21"
    type="prismatic">
    <origin
      xyz="0.015 -0.008 0"
      rpy="0 0 0" />
    <parent
      link="rsec21" />
    <child
      link="psec21" />
    <axis
      xyz="0 -1 0" />
    <limit
      lower="-0.01"
      upper="0.01"
      effort="100"
      velocity="100" />
  </joint>
  <link
    name="rsec22">
    <inertial>
      <origin
        xyz="0.0149999999999998 -0.00521814457841319 -0.0282191168584514"
        rpy="0 0 0" />
      <mass
        value="0.00900245720098042" />
      <inertia
        ixx="3.53141255495168E-06"
        ixy="-5.12518169075502E-22"
        ixz="-9.17758538051067E-21"
        iyy="4.16190674038227E-06"
        iyz="-5.8921077227065E-07"
        izz="1.0844776995209E-06" />
    </inertial>
    <visual>
      <origin
        xyz="0 0 0"
        rpy="0 0 0" />
      <geometry>
        <mesh
          filename="package://larva54/meshes/rsec22.STL" />
      </geometry>
      <material
        name="">
        <color
          rgba="0.792156862745098 0.819607843137255 0.933333333333333 1" />
      </material>
    </visual>
    <collision>
      <origin
        xyz="0 0 0"
        rpy="0 0 0" />
      <geometry>
        <mesh
          filename="package://larva54/meshes/rsec22.STL" />
      </geometry>
    </collision>
  </link>
  <joint
    name="rjoint22"
    type="revolute">
    <origin
      xyz="-0.015 -0.072 0"
      rpy="0 0 0" />
    <parent
      link="psec21" />
    <child
      link="rsec22" />
    <axis
      xyz="1 0 0" />
    <limit
      lower="-3.14"
      upper="3.14"
      effort="100"
      velocity="100" />
  </joint>
  <link
    name="psec22">
    <inertial>
      <origin
        xyz="-5.55111512312578E-17 0.051660274741943 2.22044604925031E-16"
        rpy="0 0 0" />
      <mass
        value="0.0113929064804486" />
      <inertia
        ixx="3.53005448855797E-06"
        ixy="1.49595520965315E-21"
        ixz="-1.42023912026461E-21"
        iyy="7.53550404521458E-07"
        iyz="3.04402465419514E-21"
        izz="4.19127116468425E-06" />
    </inertial>
    <visual>
      <origin
        xyz="0 0 0"
        rpy="0 0 0" />
      <geometry>
        <mesh
          filename="package://larva54/meshes/psec22.STL" />
      </geometry>
      <material
        name="">
        <color
          rgba="0.792156862745098 0.819607843137255 0.933333333333333 1" />
      </material>
    </visual>
    <collision>
      <origin
        xyz="0 0 0"
        rpy="0 0 0" />
      <geometry>
        <mesh
          filename="package://larva54/meshes/psec22.STL" />
      </geometry>
    </collision>
  </link>
  <joint
    name="pjoint22"
    type="prismatic">
    <origin
      xyz="0.015 -0.0014547 -0.0078666"
      rpy="-1.7536 0 0" />
    <parent
      link="rsec22" />
    <child
      link="psec22" />
    <axis
      xyz="0 1 0" />
    <limit
      lower="-0.01"
      upper="0.01"
      effort="100"
      velocity="100" />
  </joint>
  <link
    name="rsec23">
    <inertial>
      <origin
        xyz="0.0150577611309209 0.030463230470942 0.0140445297245173"
        rpy="0 0 0" />
      <mass
        value="0.0101124572009803" />
      <inertia
        ixx="5.21578447023891E-06"
        ixy="1.42780672512999E-08"
        ixz="6.58264855104004E-09"
        iyy="1.96895737588558E-06"
        iyz="-1.88022704105012E-06"
        izz="5.18041106258406E-06" />
    </inertial>
    <visual>
      <origin
        xyz="0 0 0"
        rpy="0 0 0" />
      <geometry>
        <mesh
          filename="package://larva54/meshes/rsec23.STL" />
      </geometry>
      <material
        name="">
        <color
          rgba="0.792156862745098 0.819607843137255 0.933333333333333 1" />
      </material>
    </visual>
    <collision>
      <origin
        xyz="0 0 0"
        rpy="0 0 0" />
      <geometry>
        <mesh
          filename="package://larva54/meshes/rsec23.STL" />
      </geometry>
    </collision>
  </link>
  <joint
    name="rjoint23"
    type="revolute">
    <origin
      xyz="-0.015462 0.084232 0"
      rpy="1.7536 0 0" />
    <parent
      link="psec22" />
    <child
      link="rsec23" />
    <axis
      xyz="1 0 0" />
    <limit
      lower="-3.14"
      upper="3.14"
      effort="100"
      velocity="100" />
  </joint>
  <link
    name="psec23">
    <inertial>
      <origin
        xyz="-8.32667268468867E-17 0.0634854251616257 -1.77635683940025E-15"
        rpy="0 0 0" />
      <mass
        value="0.0123379064804484" />
      <inertia
        ixx="4.46823934651092E-06"
        ixy="-9.17962467694886E-22"
        ixz="-2.8203589353287E-21"
        iyy="8.14817904521439E-07"
        iyz="2.38228016415272E-21"
        izz="5.18300602263718E-06" />
    </inertial>
    <visual>
      <origin
        xyz="0 0 0"
        rpy="0 0 0" />
      <geometry>
        <mesh
          filename="package://larva54/meshes/psec23.STL" />
      </geometry>
      <material
        name="">
        <color
          rgba="0.792156862745098 0.819607843137255 0.933333333333333 1" />
      </material>
    </visual>
    <collision>
      <origin
        xyz="0 0 0"
        rpy="0 0 0" />
      <geometry>
        <mesh
          filename="package://larva54/meshes/psec23.STL" />
      </geometry>
    </collision>
  </link>
  <joint
    name="pjoint23"
    type="prismatic">
    <origin
      xyz="0.015462 0.0072651 0.0033494"
      rpy="0.43199 0 0" />
    <parent
      link="rsec23" />
    <child
      link="psec23" />
    <axis
      xyz="0 1 0" />
    <limit
      lower="-0.01"
      upper="0.01"
      effort="100"
      velocity="100" />
  </joint>
  <link
    name="rsec24">
    <inertial>
      <origin
        xyz="0.0149999999999998 1.77635683940025E-15 0.010722070699781"
        rpy="0 0 0" />
      <mass
        value="0.00425747932954244" />
      <inertia
        ixx="2.63197929836907E-07"
        ixy="5.22756796039758E-22"
        ixz="1.18829818982038E-21"
        iyy="6.29591000454958E-07"
        iyz="1.05879118406788E-21"
        izz="4.58223626416461E-07" />
    </inertial>
    <visual>
      <origin
        xyz="0 0 0"
        rpy="0 0 0" />
      <geometry>
        <mesh
          filename="package://larva54/meshes/rsec24.STL" />
      </geometry>
      <material
        name="">
        <color
          rgba="0.792156862745098 0.819607843137255 0.933333333333333 1" />
      </material>
    </visual>
    <collision>
      <origin
        xyz="0 0 0"
        rpy="0 0 0" />
      <geometry>
        <mesh
          filename="package://larva54/meshes/rsec24.STL" />
      </geometry>
    </collision>
  </link>
  <joint
    name="rjoint24"
    type="revolute">
    <origin
      xyz="-0.015 0.09856 0"
      rpy="-0.43199 0 0" />
    <parent
      link="psec23" />
    <child
      link="rsec24" />
    <axis
      xyz="1 0 0" />
    <limit
      lower="-3.14"
      upper="3.14"
      effort="100"
      velocity="100" />
  </joint>
  <link
    name="psec24">
    <inertial>
      <origin
        xyz="2.77555756156289E-17 -0.0218035208950567 -2.22044604925031E-16"
        rpy="0 0 0" />
      <mass
        value="0.00694913649691771" />
      <inertia
        ixx="5.77071801345557E-07"
        ixy="-3.24751036015422E-22"
        ixz="-2.81407102715262E-22"
        iyy="4.75978173293697E-07"
        iyz="2.38228016415272E-22"
        izz="1.00011721116997E-06" />
    </inertial>
    <visual>
      <origin
        xyz="0 0 0"
        rpy="0 0 0" />
      <geometry>
        <mesh
          filename="package://larva54/meshes/psec24.STL" />
      </geometry>
      <material
        name="">
        <color
          rgba="0.792156862745098 0.819607843137255 0.933333333333333 1" />
      </material>
    </visual>
    <collision>
      <origin
        xyz="0 0 0"
        rpy="0 0 0" />
      <geometry>
        <mesh
          filename="package://larva54/meshes/psec24.STL" />
      </geometry>
    </collision>
  </link>
  <joint
    name="pjoint24"
    type="prismatic">
    <origin
      xyz="0.015 0 0.008"
      rpy="-1.5708 0 3.1416" />
    <parent
      link="rsec24" />
    <child
      link="psec24" />
    <axis
      xyz="0 -1 0" />
    <limit
      lower="-0.01"
      upper="0.01"
      effort="100"
      velocity="100" />
  </joint>
  <link
    name="link12">
    <inertial>
      <origin
        xyz="-0.000500000000000111 6.66133814775094E-16 -1.77635683940025E-15"
        rpy="0 0 0" />
      <mass
        value="5.02654824574367E-05" />
      <inertia
        ixx="4.02123859659494E-10"
        ixy="-2.63932920417233E-25"
        ixz="4.39487528496365E-28"
        iyy="2.05250720034533E-10"
        iyz="4.52364397489938E-26"
        izz="2.05250720034533E-10" />
    </inertial>
    <visual>
      <origin
        xyz="0 0 0"
        rpy="0 0 0" />
      <geometry>
        <mesh
          filename="package://larva54/meshes/link12.STL" />
      </geometry>
      <material
        name="">
        <color
          rgba="0.792156862745098 0.819607843137255 0.933333333333333 1" />
      </material>
    </visual>
    <collision>
      <origin
        xyz="0 0 0"
        rpy="0 0 0" />
      <geometry>
        <mesh
          filename="package://larva54/meshes/link12.STL" />
      </geometry>
    </collision>
  </link>
  <joint
    name="linkjoint12"
    type="continuous">
    <origin
      xyz="0.031 0 0"
      rpy="0 0 0" />
    <parent
      link="rsec21" />
    <child
      link="link12" />
    <axis
      xyz="-1 0 0" />
    <limit
      lower="-3.14"
      upper="3.14"
      effort="100"
      velocity="100" />
  </joint>
</robot>